[2025-04-20T05:56:52.739+0000] {local_task_job_runner.py:123} INFO - ::group::Pre task execution logs
[2025-04-20T05:56:52.762+0000] {taskinstance.py:2614} INFO - Dependencies all met for dep_context=non-requeueable deps ti=<TaskInstance: sqlite_data_marts_and_views.sqlite_dm_and_views manual__2025-04-20T05:56:44.029972+00:00 [queued]>
[2025-04-20T05:56:52.772+0000] {taskinstance.py:2614} INFO - Dependencies all met for dep_context=requeueable deps ti=<TaskInstance: sqlite_data_marts_and_views.sqlite_dm_and_views manual__2025-04-20T05:56:44.029972+00:00 [queued]>
[2025-04-20T05:56:52.773+0000] {taskinstance.py:2867} INFO - Starting attempt 1 of 1
[2025-04-20T05:56:53.106+0000] {taskinstance.py:2890} INFO - Executing <Task(PythonOperator): sqlite_dm_and_views> on 2025-04-20 05:56:44.029972+00:00
[2025-04-20T05:56:53.120+0000] {warnings.py:112} WARNING - /home/***/.local/lib/python3.12/site-packages/***/task/task_runner/standard_task_runner.py:70: DeprecationWarning: This process (pid=3070) is multi-threaded, use of fork() may lead to deadlocks in the child.
  pid = os.fork()

[2025-04-20T05:56:53.122+0000] {standard_task_runner.py:72} INFO - Started process 3072 to run task
[2025-04-20T05:56:53.122+0000] {standard_task_runner.py:104} INFO - Running: ['***', 'tasks', 'run', 'sqlite_data_marts_and_views', 'sqlite_dm_and_views', 'manual__2025-04-20T05:56:44.029972+00:00', '--job-id', '235', '--raw', '--subdir', 'DAGS_FOLDER/dag_sqlite_data_mart.py', '--cfg-path', '/tmp/tmpciucsako']
[2025-04-20T05:56:53.124+0000] {standard_task_runner.py:105} INFO - Job 235: Subtask sqlite_dm_and_views
[2025-04-20T05:56:53.192+0000] {task_command.py:467} INFO - Running <TaskInstance: sqlite_data_marts_and_views.sqlite_dm_and_views manual__2025-04-20T05:56:44.029972+00:00 [running]> on host 967b14145433
[2025-04-20T05:56:53.300+0000] {taskinstance.py:3134} INFO - Exporting env vars: AIRFLOW_CTX_DAG_OWNER='***' AIRFLOW_CTX_DAG_ID='sqlite_data_marts_and_views' AIRFLOW_CTX_TASK_ID='sqlite_dm_and_views' AIRFLOW_CTX_EXECUTION_DATE='2025-04-20T05:56:44.029972+00:00' AIRFLOW_CTX_TRY_NUMBER='1' AIRFLOW_CTX_DAG_RUN_ID='manual__2025-04-20T05:56:44.029972+00:00'
[2025-04-20T05:56:53.302+0000] {logging_mixin.py:190} INFO - Task instance is in running state
[2025-04-20T05:56:53.303+0000] {logging_mixin.py:190} INFO -  Previous state of the Task instance: queued
[2025-04-20T05:56:53.303+0000] {logging_mixin.py:190} INFO - Current task name:sqlite_dm_and_views state:running start_date:2025-04-20 05:56:52.763759+00:00
[2025-04-20T05:56:53.304+0000] {logging_mixin.py:190} INFO - Dag name:sqlite_data_marts_and_views and current dag run status:running
[2025-04-20T05:56:53.304+0000] {taskinstance.py:732} INFO - ::endgroup::
[2025-04-20T05:56:53.474+0000] {taskinstance.py:3313} ERROR - Task failed with exception
Traceback (most recent call last):
  File "/home/airflow/.local/lib/python3.12/site-packages/airflow/models/taskinstance.py", line 768, in _execute_task
    result = _execute_callable(context=context, **execute_callable_kwargs)
             ^^^^^^^^^^^^^^^^^^^^^^^^^^^^^^^^^^^^^^^^^^^^^^^^^^^^^^^^^^^^^
  File "/home/airflow/.local/lib/python3.12/site-packages/airflow/models/taskinstance.py", line 734, in _execute_callable
    return ExecutionCallableRunner(
           ^^^^^^^^^^^^^^^^^^^^^^^^
  File "/home/airflow/.local/lib/python3.12/site-packages/airflow/utils/operator_helpers.py", line 252, in run
    return self.func(*args, **kwargs)
           ^^^^^^^^^^^^^^^^^^^^^^^^^^
  File "/home/airflow/.local/lib/python3.12/site-packages/airflow/models/baseoperator.py", line 424, in wrapper
    return func(self, *args, **kwargs)
           ^^^^^^^^^^^^^^^^^^^^^^^^^^^
  File "/home/airflow/.local/lib/python3.12/site-packages/airflow/operators/python.py", line 238, in execute
    return_value = self.execute_callable()
                   ^^^^^^^^^^^^^^^^^^^^^^^
  File "/home/airflow/.local/lib/python3.12/site-packages/airflow/operators/python.py", line 256, in execute_callable
    return runner.run(*self.op_args, **self.op_kwargs)
           ^^^^^^^^^^^^^^^^^^^^^^^^^^^^^^^^^^^^^^^^^^^
  File "/home/airflow/.local/lib/python3.12/site-packages/airflow/utils/operator_helpers.py", line 252, in run
    return self.func(*args, **kwargs)
           ^^^^^^^^^^^^^^^^^^^^^^^^^^
  File "/opt/airflow/dags/dag_sqlite_data_mart.py", line 69, in create_sqlite_data_marts_and_views
    conn.execute("""
sqlite3.OperationalError: no such column: f.transaction_date
[2025-04-20T05:56:53.499+0000] {logging_mixin.py:190} INFO - Task instance in failure state
[2025-04-20T05:56:53.500+0000] {logging_mixin.py:190} INFO - Task start:2025-04-20 05:56:52.763759+00:00 end:2025-04-20 05:56:53.499082+00:00 duration:0.735323
[2025-04-20T05:56:53.501+0000] {logging_mixin.py:190} INFO - Task:<Task(PythonOperator): sqlite_dm_and_views> dag:<DAG: sqlite_data_marts_and_views> dagrun:<DagRun sqlite_data_marts_and_views @ 2025-04-20 05:56:44.029972+00:00: manual__2025-04-20T05:56:44.029972+00:00, state:running, queued_at: 2025-04-20 05:56:44.109214+00:00. externally triggered: True>
[2025-04-20T05:56:53.501+0000] {logging_mixin.py:190} INFO - Failure caused by no such column: f.transaction_date
[2025-04-20T05:56:53.502+0000] {taskinstance.py:1226} INFO - Marking task as FAILED. dag_id=sqlite_data_marts_and_views, task_id=sqlite_dm_and_views, run_id=manual__2025-04-20T05:56:44.029972+00:00, execution_date=20250420T055644, start_date=20250420T055652, end_date=20250420T055653
[2025-04-20T05:56:53.538+0000] {taskinstance.py:341} INFO - ::group::Post task execution logs
[2025-04-20T05:56:53.539+0000] {standard_task_runner.py:124} ERROR - Failed to execute job 235 for task sqlite_dm_and_views (no such column: f.transaction_date; 3072)
Traceback (most recent call last):
  File "/home/airflow/.local/lib/python3.12/site-packages/airflow/task/task_runner/standard_task_runner.py", line 117, in _start_by_fork
    ret = args.func(args, dag=self.dag)
          ^^^^^^^^^^^^^^^^^^^^^^^^^^^^^
  File "/home/airflow/.local/lib/python3.12/site-packages/airflow/cli/cli_config.py", line 49, in command
    return func(*args, **kwargs)
           ^^^^^^^^^^^^^^^^^^^^^
  File "/home/airflow/.local/lib/python3.12/site-packages/airflow/utils/cli.py", line 116, in wrapper
    return f(*args, **kwargs)
           ^^^^^^^^^^^^^^^^^^
  File "/home/airflow/.local/lib/python3.12/site-packages/airflow/cli/commands/task_command.py", line 483, in task_run
    task_return_code = _run_task_by_selected_method(args, _dag, ti)
                       ^^^^^^^^^^^^^^^^^^^^^^^^^^^^^^^^^^^^^^^^^^^^
  File "/home/airflow/.local/lib/python3.12/site-packages/airflow/cli/commands/task_command.py", line 256, in _run_task_by_selected_method
    return _run_raw_task(args, ti)
           ^^^^^^^^^^^^^^^^^^^^^^^
  File "/home/airflow/.local/lib/python3.12/site-packages/airflow/cli/commands/task_command.py", line 341, in _run_raw_task
    return ti._run_raw_task(
           ^^^^^^^^^^^^^^^^^
  File "/home/airflow/.local/lib/python3.12/site-packages/airflow/utils/session.py", line 97, in wrapper
    return func(*args, session=session, **kwargs)
           ^^^^^^^^^^^^^^^^^^^^^^^^^^^^^^^^^^^^^^
  File "/home/airflow/.local/lib/python3.12/site-packages/airflow/models/taskinstance.py", line 3006, in _run_raw_task
    return _run_raw_task(
           ^^^^^^^^^^^^^^
  File "/home/airflow/.local/lib/python3.12/site-packages/airflow/models/taskinstance.py", line 274, in _run_raw_task
    TaskInstance._execute_task_with_callbacks(
  File "/home/airflow/.local/lib/python3.12/site-packages/airflow/models/taskinstance.py", line 3161, in _execute_task_with_callbacks
    result = self._execute_task(context, task_orig)
             ^^^^^^^^^^^^^^^^^^^^^^^^^^^^^^^^^^^^^^
  File "/home/airflow/.local/lib/python3.12/site-packages/airflow/models/taskinstance.py", line 3185, in _execute_task
    return _execute_task(self, context, task_orig)
           ^^^^^^^^^^^^^^^^^^^^^^^^^^^^^^^^^^^^^^^
  File "/home/airflow/.local/lib/python3.12/site-packages/airflow/models/taskinstance.py", line 768, in _execute_task
    result = _execute_callable(context=context, **execute_callable_kwargs)
             ^^^^^^^^^^^^^^^^^^^^^^^^^^^^^^^^^^^^^^^^^^^^^^^^^^^^^^^^^^^^^
  File "/home/airflow/.local/lib/python3.12/site-packages/airflow/models/taskinstance.py", line 734, in _execute_callable
    return ExecutionCallableRunner(
           ^^^^^^^^^^^^^^^^^^^^^^^^
  File "/home/airflow/.local/lib/python3.12/site-packages/airflow/utils/operator_helpers.py", line 252, in run
    return self.func(*args, **kwargs)
           ^^^^^^^^^^^^^^^^^^^^^^^^^^
  File "/home/airflow/.local/lib/python3.12/site-packages/airflow/models/baseoperator.py", line 424, in wrapper
    return func(self, *args, **kwargs)
           ^^^^^^^^^^^^^^^^^^^^^^^^^^^
  File "/home/airflow/.local/lib/python3.12/site-packages/airflow/operators/python.py", line 238, in execute
    return_value = self.execute_callable()
                   ^^^^^^^^^^^^^^^^^^^^^^^
  File "/home/airflow/.local/lib/python3.12/site-packages/airflow/operators/python.py", line 256, in execute_callable
    return runner.run(*self.op_args, **self.op_kwargs)
           ^^^^^^^^^^^^^^^^^^^^^^^^^^^^^^^^^^^^^^^^^^^
  File "/home/airflow/.local/lib/python3.12/site-packages/airflow/utils/operator_helpers.py", line 252, in run
    return self.func(*args, **kwargs)
           ^^^^^^^^^^^^^^^^^^^^^^^^^^
  File "/opt/airflow/dags/dag_sqlite_data_mart.py", line 69, in create_sqlite_data_marts_and_views
    conn.execute("""
sqlite3.OperationalError: no such column: f.transaction_date
[2025-04-20T05:56:53.579+0000] {local_task_job_runner.py:266} INFO - Task exited with return code 1
[2025-04-20T05:56:53.602+0000] {taskinstance.py:3901} INFO - 0 downstream tasks scheduled from follow-on schedule check
[2025-04-20T05:56:53.604+0000] {local_task_job_runner.py:245} INFO - ::endgroup::
