[2025-04-06T14:17:18.317+0000] {local_task_job_runner.py:123} INFO - ::group::Pre task execution logs
[2025-04-06T14:17:18.368+0000] {taskinstance.py:2614} INFO - Dependencies all met for dep_context=non-requeueable deps ti=<TaskInstance: dag_data_quality.check_transaction_id_quality scheduled__2025-04-05T00:00:00+00:00 [queued]>
[2025-04-06T14:17:18.394+0000] {taskinstance.py:2614} INFO - Dependencies all met for dep_context=requeueable deps ti=<TaskInstance: dag_data_quality.check_transaction_id_quality scheduled__2025-04-05T00:00:00+00:00 [queued]>
[2025-04-06T14:17:18.395+0000] {taskinstance.py:2867} INFO - Starting attempt 1 of 2
[2025-04-06T14:17:18.777+0000] {taskinstance.py:2890} INFO - Executing <Task(_PythonDecoratedOperator): check_transaction_id_quality> on 2025-04-05 00:00:00+00:00
[2025-04-06T14:17:18.837+0000] {warnings.py:112} WARNING - /home/***/.local/lib/python3.12/site-packages/***/task/task_runner/standard_task_runner.py:70: DeprecationWarning: This process (pid=1331) is multi-threaded, use of fork() may lead to deadlocks in the child.
  pid = os.fork()

[2025-04-06T14:17:18.841+0000] {standard_task_runner.py:104} INFO - Running: ['***', 'tasks', 'run', 'dag_data_quality', 'check_transaction_id_quality', 'scheduled__2025-04-05T00:00:00+00:00', '--job-id', '53', '--raw', '--subdir', 'DAGS_FOLDER/dag_data_quality.py', '--cfg-path', '/tmp/tmpe3qma4p8']
[2025-04-06T14:17:18.844+0000] {standard_task_runner.py:72} INFO - Started process 1337 to run task
[2025-04-06T14:17:18.845+0000] {standard_task_runner.py:105} INFO - Job 53: Subtask check_transaction_id_quality
[2025-04-06T14:17:19.327+0000] {task_command.py:467} INFO - Running <TaskInstance: dag_data_quality.check_transaction_id_quality scheduled__2025-04-05T00:00:00+00:00 [running]> on host 2e277e0df613
[2025-04-06T14:17:20.122+0000] {taskinstance.py:3134} INFO - Exporting env vars: AIRFLOW_CTX_DAG_EMAIL='laurenziusjulioanreaja@mail.ugm.ac.id,selvianisacahyamukti@mail.ugm.ac.id,yudypratamafanggidae@mail.ugm.ac.id' AIRFLOW_CTX_DAG_OWNER='julio' AIRFLOW_CTX_DAG_ID='dag_data_quality' AIRFLOW_CTX_TASK_ID='check_transaction_id_quality' AIRFLOW_CTX_EXECUTION_DATE='2025-04-05T00:00:00+00:00' AIRFLOW_CTX_TRY_NUMBER='1' AIRFLOW_CTX_DAG_RUN_ID='scheduled__2025-04-05T00:00:00+00:00'
[2025-04-06T14:17:20.148+0000] {logging_mixin.py:190} INFO - Task instance is in running state
[2025-04-06T14:17:20.150+0000] {logging_mixin.py:190} INFO -  Previous state of the Task instance: queued
[2025-04-06T14:17:20.152+0000] {logging_mixin.py:190} INFO - Current task name:check_transaction_id_quality state:running start_date:2025-04-06 14:17:18.370752+00:00
[2025-04-06T14:17:20.153+0000] {logging_mixin.py:190} INFO - Dag name:dag_data_quality and current dag run status:running
[2025-04-06T14:17:20.156+0000] {taskinstance.py:732} INFO - ::endgroup::
[2025-04-06T14:17:20.927+0000] {taskinstance.py:3313} ERROR - Task failed with exception
Traceback (most recent call last):
  File "/home/airflow/.local/lib/python3.12/site-packages/airflow/models/taskinstance.py", line 768, in _execute_task
    result = _execute_callable(context=context, **execute_callable_kwargs)
             ^^^^^^^^^^^^^^^^^^^^^^^^^^^^^^^^^^^^^^^^^^^^^^^^^^^^^^^^^^^^^
  File "/home/airflow/.local/lib/python3.12/site-packages/airflow/models/taskinstance.py", line 734, in _execute_callable
    return ExecutionCallableRunner(
           ^^^^^^^^^^^^^^^^^^^^^^^^
  File "/home/airflow/.local/lib/python3.12/site-packages/airflow/utils/operator_helpers.py", line 252, in run
    return self.func(*args, **kwargs)
           ^^^^^^^^^^^^^^^^^^^^^^^^^^
  File "/home/airflow/.local/lib/python3.12/site-packages/airflow/models/baseoperator.py", line 424, in wrapper
    return func(self, *args, **kwargs)
           ^^^^^^^^^^^^^^^^^^^^^^^^^^^
  File "/home/airflow/.local/lib/python3.12/site-packages/airflow/decorators/base.py", line 266, in execute
    return_value = super().execute(context)
                   ^^^^^^^^^^^^^^^^^^^^^^^^
  File "/home/airflow/.local/lib/python3.12/site-packages/airflow/models/baseoperator.py", line 424, in wrapper
    return func(self, *args, **kwargs)
           ^^^^^^^^^^^^^^^^^^^^^^^^^^^
  File "/home/airflow/.local/lib/python3.12/site-packages/airflow/operators/python.py", line 238, in execute
    return_value = self.execute_callable()
                   ^^^^^^^^^^^^^^^^^^^^^^^
  File "/home/airflow/.local/lib/python3.12/site-packages/airflow/operators/python.py", line 256, in execute_callable
    return runner.run(*self.op_args, **self.op_kwargs)
           ^^^^^^^^^^^^^^^^^^^^^^^^^^^^^^^^^^^^^^^^^^^
  File "/home/airflow/.local/lib/python3.12/site-packages/airflow/utils/operator_helpers.py", line 252, in run
    return self.func(*args, **kwargs)
           ^^^^^^^^^^^^^^^^^^^^^^^^^^
  File "/opt/airflow/dags/dag_data_quality.py", line 54, in check_transaction_id_quality
    raise ValueError(f"❌ Ditemukan {dup} Transaction_ID yang duplikat!")
ValueError: ❌ Ditemukan 500 Transaction_ID yang duplikat!
[2025-04-06T14:17:21.029+0000] {logging_mixin.py:190} INFO - Task instance in failure state
[2025-04-06T14:17:21.030+0000] {logging_mixin.py:190} INFO - Task start:2025-04-06 14:17:18.370752+00:00 end:2025-04-06 14:17:21.027775+00:00 duration:2.657023
[2025-04-06T14:17:21.031+0000] {logging_mixin.py:190} INFO - Task:<Task(_PythonDecoratedOperator): check_transaction_id_quality> dag:<DAG: dag_data_quality> dagrun:<DagRun dag_data_quality @ 2025-04-05 00:00:00+00:00: scheduled__2025-04-05T00:00:00+00:00, state:running, queued_at: 2025-04-06 14:16:54.961824+00:00. externally triggered: False>
[2025-04-06T14:17:21.032+0000] {logging_mixin.py:190} INFO - Failure caused by ❌ Ditemukan 500 Transaction_ID yang duplikat!
[2025-04-06T14:17:21.032+0000] {taskinstance.py:1226} INFO - Marking task as UP_FOR_RETRY. dag_id=dag_data_quality, task_id=check_transaction_id_quality, run_id=scheduled__2025-04-05T00:00:00+00:00, execution_date=20250405T000000, start_date=20250406T141718, end_date=20250406T141721
[2025-04-06T14:17:21.296+0000] {taskinstance.py:341} INFO - ::group::Post task execution logs
[2025-04-06T14:17:21.298+0000] {standard_task_runner.py:124} ERROR - Failed to execute job 53 for task check_transaction_id_quality (❌ Ditemukan 500 Transaction_ID yang duplikat!; 1337)
Traceback (most recent call last):
  File "/home/airflow/.local/lib/python3.12/site-packages/airflow/task/task_runner/standard_task_runner.py", line 117, in _start_by_fork
    ret = args.func(args, dag=self.dag)
          ^^^^^^^^^^^^^^^^^^^^^^^^^^^^^
  File "/home/airflow/.local/lib/python3.12/site-packages/airflow/cli/cli_config.py", line 49, in command
    return func(*args, **kwargs)
           ^^^^^^^^^^^^^^^^^^^^^
  File "/home/airflow/.local/lib/python3.12/site-packages/airflow/utils/cli.py", line 116, in wrapper
    return f(*args, **kwargs)
           ^^^^^^^^^^^^^^^^^^
  File "/home/airflow/.local/lib/python3.12/site-packages/airflow/cli/commands/task_command.py", line 483, in task_run
    task_return_code = _run_task_by_selected_method(args, _dag, ti)
                       ^^^^^^^^^^^^^^^^^^^^^^^^^^^^^^^^^^^^^^^^^^^^
  File "/home/airflow/.local/lib/python3.12/site-packages/airflow/cli/commands/task_command.py", line 256, in _run_task_by_selected_method
    return _run_raw_task(args, ti)
           ^^^^^^^^^^^^^^^^^^^^^^^
  File "/home/airflow/.local/lib/python3.12/site-packages/airflow/cli/commands/task_command.py", line 341, in _run_raw_task
    return ti._run_raw_task(
           ^^^^^^^^^^^^^^^^^
  File "/home/airflow/.local/lib/python3.12/site-packages/airflow/utils/session.py", line 97, in wrapper
    return func(*args, session=session, **kwargs)
           ^^^^^^^^^^^^^^^^^^^^^^^^^^^^^^^^^^^^^^
  File "/home/airflow/.local/lib/python3.12/site-packages/airflow/models/taskinstance.py", line 3006, in _run_raw_task
    return _run_raw_task(
           ^^^^^^^^^^^^^^
  File "/home/airflow/.local/lib/python3.12/site-packages/airflow/models/taskinstance.py", line 274, in _run_raw_task
    TaskInstance._execute_task_with_callbacks(
  File "/home/airflow/.local/lib/python3.12/site-packages/airflow/models/taskinstance.py", line 3161, in _execute_task_with_callbacks
    result = self._execute_task(context, task_orig)
             ^^^^^^^^^^^^^^^^^^^^^^^^^^^^^^^^^^^^^^
  File "/home/airflow/.local/lib/python3.12/site-packages/airflow/models/taskinstance.py", line 3185, in _execute_task
    return _execute_task(self, context, task_orig)
           ^^^^^^^^^^^^^^^^^^^^^^^^^^^^^^^^^^^^^^^
  File "/home/airflow/.local/lib/python3.12/site-packages/airflow/models/taskinstance.py", line 768, in _execute_task
    result = _execute_callable(context=context, **execute_callable_kwargs)
             ^^^^^^^^^^^^^^^^^^^^^^^^^^^^^^^^^^^^^^^^^^^^^^^^^^^^^^^^^^^^^
  File "/home/airflow/.local/lib/python3.12/site-packages/airflow/models/taskinstance.py", line 734, in _execute_callable
    return ExecutionCallableRunner(
           ^^^^^^^^^^^^^^^^^^^^^^^^
  File "/home/airflow/.local/lib/python3.12/site-packages/airflow/utils/operator_helpers.py", line 252, in run
    return self.func(*args, **kwargs)
           ^^^^^^^^^^^^^^^^^^^^^^^^^^
  File "/home/airflow/.local/lib/python3.12/site-packages/airflow/models/baseoperator.py", line 424, in wrapper
    return func(self, *args, **kwargs)
           ^^^^^^^^^^^^^^^^^^^^^^^^^^^
  File "/home/airflow/.local/lib/python3.12/site-packages/airflow/decorators/base.py", line 266, in execute
    return_value = super().execute(context)
                   ^^^^^^^^^^^^^^^^^^^^^^^^
  File "/home/airflow/.local/lib/python3.12/site-packages/airflow/models/baseoperator.py", line 424, in wrapper
    return func(self, *args, **kwargs)
           ^^^^^^^^^^^^^^^^^^^^^^^^^^^
  File "/home/airflow/.local/lib/python3.12/site-packages/airflow/operators/python.py", line 238, in execute
    return_value = self.execute_callable()
                   ^^^^^^^^^^^^^^^^^^^^^^^
  File "/home/airflow/.local/lib/python3.12/site-packages/airflow/operators/python.py", line 256, in execute_callable
    return runner.run(*self.op_args, **self.op_kwargs)
           ^^^^^^^^^^^^^^^^^^^^^^^^^^^^^^^^^^^^^^^^^^^
  File "/home/airflow/.local/lib/python3.12/site-packages/airflow/utils/operator_helpers.py", line 252, in run
    return self.func(*args, **kwargs)
           ^^^^^^^^^^^^^^^^^^^^^^^^^^
  File "/opt/airflow/dags/dag_data_quality.py", line 54, in check_transaction_id_quality
    raise ValueError(f"❌ Ditemukan {dup} Transaction_ID yang duplikat!")
ValueError: ❌ Ditemukan 500 Transaction_ID yang duplikat!
[2025-04-06T14:17:21.361+0000] {local_task_job_runner.py:266} INFO - Task exited with return code 1
[2025-04-06T14:17:21.389+0000] {local_task_job_runner.py:245} INFO - ::endgroup::
